Workbook
Name Slicer_Campaign_name: #N/A
Name Slicer_DAY_TYPE: #N/A
Name Slicer_GEO: #N/A

Sheet Marketing
A1: id | B1: MONTH | C1: DAY | D1: Calendar Date | E1: Campaign name | F1: Campaign category | G1: Campaign id | H1: Impressions | I1: Mark spent | J1: Clicks | K1: Leads | L1: Orders | M1: Revenue | N1: ROMI % | O1: CTR % | P1: CR1(VL) % | Q1: CR2(LO) % | R1: AVERAGE ORDER VALUE | S1: COST PER CLICK | T1: COST PER LEAD | U1: GROSS PROFIT | V1: CAC | W1: GEO | X1: GEO2 | Y1: DAY TYPE
A2: 1 | B2: =TEXT(Marketing!$D2,"MMMM") -> February | C2: =TEXT(Marketing!$D2,"DDDD") -> Monday | D2: 44228 | E2: facebook_tier1 | F2: social | G2: 349043 | H2: 148263 | I2: 7307.37 | J2: 1210 | K2: 13 | L2: 1 | M2: 4981 | N2: -0.0031835941 | O2: 8.1611731e-05 | P2: 0.00010743802 | Q2: 0.00076923077 | R2: =IF(Marketing!$L2=0, 0, Marketing!$M2/Marketing!$L2) -> 4981 | S2: =IF(Marketing!$J2=0,0,Marketing!$I2/Marketing!$J2) -> 6.0391488 | T2: =IF(Marketing!$K2=0,0,Marketing!$I2/Marketing!$K2) -> 562.10538 | U2: =Marketing!$M2 - Marketing!$I2 -> -2326.37 | V2: =IF(Marketing!$L2=0,0,Marketing!$I2/Marketing!$L2) -> 7307.37 | W2: =IF(ISNUMBER(SEARCH("tier1",Marketing!$E2)),"Tier 1","Tier 2") -> Tier 1 | X2: =IF(ISNUMBER(SEARCH("tier1", E2)), "Tier 1", IF(ISNUMBER(SEARCH("tier2", E2)), "Tier 2", "Tier 2")) -> Tier 1 | Y2: =IF(WEEKDAY(Marketing!$D2,2)<6,"Weekday","Weekend") -> Weekday
A3: 2 | B3: =TEXT(Marketing!$D3,"MMMM") -> February | C3: =TEXT(Marketing!$D3,"DDDD") -> Monday | D3: 44228 | E3: Facebook_tier2 | F3: social | G3: 348934 | H3: 220688 | I3: 16300.2 | J3: 1640 | K3: 48 | L3: 3 | M3: 14962 | N3: -0.00082097152 | O3: 7.4313057e-05 | P3: 0.00029268293 | Q3: 0.000625 | R3: =IF(Marketing!$L3=0, 0, Marketing!$M3/Marketing!$L3) -> 4987.3333 | S3: =IF(Marketing!$J3=0,0,Marketing!$I3/Marketing!$J3) -> 9.9391463 | T3: =IF(Marketing!$K3=0,0,Marketing!$I3/Marketing!$K3) -> 339.5875 | U3: =Marketing!$M3 - Marketing!$I3 -> -1338.2 | V3: =IF(Marketing!$L3=0,0,Marketing!$I3/Marketing!$L3) -> 5433.4 | W3: =IF(ISNUMBER(SEARCH("tier1",Marketing!$E3)),"Tier 1","Tier 2") -> Tier 2 | X3: =IF(ISNUMBER(SEARCH("tier1", E3)), "Tier 1", IF(ISNUMBER(SEARCH("tier2", E3)), "Tier 2", "Tier 2")) -> Tier 2 | Y3: =IF(WEEKDAY(Marketing!$D3,2)<6,"Weekday","Weekend") -> Weekday
A4: 3 | B4: =TEXT(Marketing!$D4,"MMMM") -> February | C4: =TEXT(Marketing!$D4,"DDDD") -> Monday | D4: 44228 | E4: google_hot | F4: search | G4: 89459845 | H4: 22850 | I4: 5221.6 | J4: 457 | K4: 9 | L4: 1 | M4: 7981 | N4: 0.0052845871 | O4: 0.0002 | P4: 0.00019693654 | Q4: 0.0011111111 | R4: =IF(Marketing!$L4=0, 0, Marketing!$M4/Marketing!$L4) -> 7981 | S4: =IF(Marketing!$J4=0,0,Marketing!$I4/Marketing!$J4) -> 11.425821 | T4: =IF(Marketing!$K4=0,0,Marketing!$I4/Marketing!$K4) -> 580.17778 | U4: =Marketing!$M4 - Marketing!$I4 -> 2759.4 | V4: =IF(Marketing!$L4=0,0,Marketing!$I4/Marketing!$L4) -> 5221.6 | W4: =IF(ISNUMBER(SEARCH("tier1",Marketing!$E4)),"Tier 1","Tier 2") -> Tier 2 | X4: =IF(ISNUMBER(SEARCH("tier1", E4)), "Tier 1", IF(ISNUMBER(SEARCH("tier2", E4)), "Tier 2", "Tier 2")) -> Tier 2 | Y4: =IF(WEEKDAY(Marketing!$D4,2)<6,"Weekday","Weekend") -> Weekday
A5: 4 | B5: =TEXT(Marketing!$D5,"MMMM") -> February | C5: =TEXT(Marketing!$D5,"DDDD") -> Monday | D5: 44228 | E5: google_wide | F5: search | G5: 127823 | H5: 147038 | I5: 6037 | J5: 1196 | K5: 24 | L5: 1 | M5: 2114 | N5: -0.0064982607 | O5: 8.1339518e-05 | P5: 0.0002006689 | Q5: 0.00041666667 | R5: =IF(Marketing!$L5=0, 0, Marketing!$M5/Marketing!$L5) -> 2114 | S5: =IF(Marketing!$J5=0,0,Marketing!$I5/Marketing!$J5) -> 5.0476589 | T5: =IF(Marketing!$K5=0,0,Marketing!$I5/Marketing!$K5) -> 251.54167 | U5: =Marketing!$M5 - Marketing!$I5 -> -3923 | V5: =IF(Marketing!$L5=0,0,Marketing!$I5/Marketing!$L5) -> 6037 | W5: =IF(ISNUMBER(SEARCH("tier1",Marketing!$E5)),"Tier 1","Tier 2") -> Tier 2 | X5: =IF(ISNUMBER(SEARCH("tier1", E5)), "Tier 1", IF(ISNUMBER(SEARCH("tier2", E5)), "Tier 2", "Tier 2")) -> Tier 2 | Y5: =IF(WEEKDAY(Marketing!$D5,2)<6,"Weekday","Weekend") -> Weekday
A6: 5 | B6: =TEXT(Marketing!$D6,"MMMM") -> February | C6: =TEXT(Marketing!$D6,"DDDD") -> Monday | D6: 44228 | E6: youtube_blogger | F6: influencer | G6: 10934 | H6: 225800 | I6: 29962.2 | J6: 2258 | K6: 49 | L6: 10 | M6: 84490 | N6: 0.018198864 | O6: 0.0001 | P6: 0.0002170062 | Q6: 0.0020408163 | R6: =IF(Marketing!$L6=0, 0, Marketing!$M6/Marketing!$L6) -> 8449 | S6: =IF(Marketing!$J6=0,0,Marketing!$I6/Marketing!$J6) -> 13.269353 | T6: =IF(Marketing!$K6=0,0,Marketing!$I6/Marketing!$K6) -> 611.47347 | U6: =Marketing!$M6 - Marketing!$I6 -> 54527.8 | V6: =IF(Marketing!$L6=0,0,Marketing!$I6/Marketing!$L6) -> 2996.22 | W6: =IF(ISNUMBER(SEARCH("tier1",Marketing!$E6)),"Tier 1","Tier 2") -> Tier 2 | X6: =IF(ISNUMBER(SEARCH("tier1", E6)), "Tier 1", IF(ISNUMBER(SEARCH("tier2", E6)), "Tier 2", "Tier 2")) -> Tier 2 | Y6: =IF(WEEKDAY(Marketing!$D6,2)<6,"Weekday","Weekend") -> Weekday
A7: 6 | B7: =TEXT(Marketing!$D7,"MMMM") -> February | C7: =TEXT(Marketing!$D7,"DDDD") -> Monday | D7: 44228 | E7: instagram_tier1 | F7: social | G7: 9034945 | H7: 444857 | I7: 9540.01 | J7: 1342 | K7: 27 | L7: 3 | M7: 17943 | N7: 0.0088081564 | O7: 3.0166997e-05 | P7: 0.00020119225 | Q7: 0.0011111111 | R7: =IF(Marketing!$L7=0, 0, Marketing!$M7/Marketing!$L7) -> 5981 | S7: =IF(Marketing!$J7=0,0,Marketing!$I7/Marketing!$J7) -> 7.1088003 | T7: =IF(Marketing!$K7=0,0,Marketing!$I7/Marketing!$K7) -> 353.3337 | U7: =Marketing!$M7 - Marketing!$I7 -> 8402.99 | V7: =IF(Marketing!$L7=0,0,Marketing!$I7/Marketing!$L7) -> 3180.0033 | W7: =IF(ISNUMBER(SEARCH("tier1",Marketing!$E7)),"Tier 1","Tier 2") -> Tier 1 | X7: =IF(ISNUMBER(SEARCH("tier1", E7)), "Tier 1", IF(ISNUMBER(SEARCH("tier2", E7)), "Tier 2", "Tier 2")) -> Tier 1 | Y7: =IF(WEEKDAY(Marketing!$D7,2)<6,"Weekday","Weekend") -> Weekday
A8: 7 | B8: =TEXT(Marketing!$D8,"MMMM") -> February | C8: =TEXT(Marketing!$D8,"DDDD") -> Monday | D8: 44228 | E8: instagram_tier2 | F8: social | G8: 983498 | H8: 511200 | I8: 3648.9 | J8: 2556 | K8: 94 | L8: 1 | M8: 1981 | N8: -0.0045709666 | O8: 5e-05 | P8: 0.00036776213 | Q8: 0.00010638298 | R8: =IF(Marketing!$L8=0, 0, Marketing!$M8/Marketing!$L8) -> 1981 | S8: =IF(Marketing!$J8=0,0,Marketing!$I8/Marketing!$J8) -> 1.4275822 | T8: =IF(Marketing!$K8=0,0,Marketing!$I8/Marketing!$K8) -> 38.818085 | U8: =Marketing!$M8 - Marketing!$I8 -> -1667.9 | V8: =IF(Marketing!$L8=0,0,Marketing!$I8/Marketing!$L8) -> 3648.9 | W8: =IF(ISNUMBER(SEARCH("tier1",Marketing!$E8)),"Tier 1","Tier 2") -> Tier 2 | X8: =IF(ISNUMBER(SEARCH("tier1", E8)), "Tier 1", IF(ISNUMBER(SEARCH("tier2", E8)), "Tier 2", "Tier 2")) -> Tier 2 | Y8: =IF(WEEKDAY(Marketing!$D8,2)<6,"Weekday","Weekend") -> Weekday
A9: 8 | B9: =TEXT(Marketing!$D9,"MMMM") -> February | C9: =TEXT(Marketing!$D9,"DDDD") -> Monday | D9: 44228 | E9: facebook_retargeting | F9: social | G9: 4387490 | H9: 5544 | I9: 1293.55 | J9: 148 | K9: 3 | L9: 1 | M9: 4981 | N9: 0.028506436 | O9: 0.00026695527 | P9: 0.0002027027 | Q9: 0.0033333333 | R9: =IF(Marketing!$L9=0, 0, Marketing!$M9/Marketing!$L9) -> 4981 | S9: =IF(Marketing!$J9=0,0,Marketing!$I9/Marketing!$J9) -> 8.7402027 | T9: =IF(Marketing!$K9=0,0,Marketing!$I9/Marketing!$K9) -> 431.18333 | U9: =Marketing!$M9 - Marketing!$I9 -> 3687.45 | V9: =IF(Marketing!$L9=0,0,Marketing!$I9/Marketing!$L9) -> 1293.55 | W9: =IF(ISNUMBER(SEARCH("tier1",Marketing!$E9)),"Tier 1","Tier 2") -> Tier 2 | X9: =IF(ISNUMBER(SEARCH("tier1", E9)), "Tier 1", IF(ISNUMBER(SEARCH("tier2", E9)), "Tier 2", "Tier 2")) -> Tier 2 | Y9: =IF(WEEKDAY(Marketing!$D9,2)<6,"Weekday","Weekend") -> Weekday
A10: 9 | B10: =TEXT(Marketing!$D10,"MMMM") -> February | C10: =TEXT(Marketing!$D10,"DDDD") -> Monday | D10: 44228 | E10: facebook_lal | F10: social | G10: 544756 | H10: 56916 | I10: 16997.8 | J10: 596 | K10: 14 | L10: 2 | M10: 4162 | N10: -0.0075514478 | O10: 0.00010471572 | P10: 0.00023489933 | Q10: 0.0014285714 | R10: =IF(Marketing!$L10=0, 0, Marketing!$M10/Marketing!$L10) -> 2081 | S10: =IF(Marketing!$J10=0,0,Marketing!$I10/Marketing!$J10) -> 28.519799 | T10: =IF(Marketing!$K10=0,0,Marketing!$I10/Marketing!$K10) -> 1214.1286 | U10: =Marketing!$M10 - Marketing!$I10 -> -12835.8 | V10: =IF(Marketing!$L10=0,0,Marketing!$I10/Marketing!$L10) -> 8498.9 | W10: =IF(ISNUMBER(SEARCH("tier1",Marketing!$E10)),"Tier 1","Tier 2") -> Tier 2 | X10: =IF(ISNUMBER(SEARCH("tier1", E10)), "Tier 1", IF(ISNUMBER(SEARCH("tier2", E10)), "Tier 2", "Tier 2")) -> Tier 2 | Y10: =IF(WEEKDAY(Marketing!$D10,2)<6,"Weekday","Weekend") -> Weekday
A11: 10 | B11: =TEXT(Marketing!$D11,"MMMM") -> February | C11: =TEXT(Marketing!$D11,"DDDD") -> Monday | D11: 44228 | E11: instagram_blogger | F11: influencer | G11: 374754 | H11: 120436 | I11: 23604.1 | J11: 1498 | K11: 49 | L11: 7 | M11: 39081 | N11: 0.0065568694 | O11: 0.00012438141 | P11: 0.0003271028 | Q11: 0.0014285714 | R11: =IF(Marketing!$L11=0, 0, Marketing!$M11/Marketing!$L11) -> 5583 | S11: =IF(Marketing!$J11=0,0,Marketing!$I11/Marketing!$J11) -> 15.757076 | T11: =IF(Marketing!$K11=0,0,Marketing!$I11/Marketing!$K11) -> 481.71633 | U11: =Marketing!$M11 - Marketing!$I11 -> 15476.9 | V11: =IF(Marketing!$L11=0,0,Marketing!$I11/Marketing!$L11) -> 3372.0143 | W11: =IF(ISNUMBER(SEARCH("tier1",Marketing!$E11)),"Tier 1","Tier 2") -> Tier 2 | X11: =IF(ISNUMBER(SEARCH("tier1", E11)), "Tier 1", IF(ISNUMBER(SEARCH("tier2", E11)), "Tier 2", "Tier 2")) -> Tier 2 | Y11: =IF(WEEKDAY(Marketing!$D11,2)<6,"Weekday","Weekend") -> Weekday
A12: 11 | B12: =TEXT(Marketing!$D12,"MMMM") -> February | C12: =TEXT(Marketing!$D12,"DDDD") -> Monday | D12: 44228 | E12: banner_partner | F12: media | G12: 39889 | H12: 20900000 | I12: 931.99 | J12: 2090 | K12: 3 | L12: 0 | M12: 0 | N12: -0.01 | O12: 1e-06 | P12: 1.4354067e-05 | Q12: 0 | R12: =IF(Marketing!$L12=0, 0, Marketing!$M12/Marketing!$L12) -> 0 | S12: =IF(Marketing!$J12=0,0,Marketing!$I12/Marketing!$J12) -> 0.44592823 | T12: =IF(Marketing!$K12=0,0,Marketing!$I12/Marketing!$K12) -> 310.66333 | U12: =Marketing!$M12 - Marketing!$I12 -> -931.99 | V12: =IF(Marketing!$L12=0,0,Marketing!$I12/Marketing!$L12) -> 0 | W12: =IF(ISNUMBER(SEARCH("tier1",Marketing!$E12)),"Tier 1","Tier 2") -> Tier 2 | X12: =IF(ISNUMBER(SEARCH("tier1", E12)), "Tier 1", IF(ISNUMBER(SEARCH("tier2", E12)), "Tier 2", "Tier 2")) -> Tier 2 | Y12: =IF(WEEKDAY(Marketing!$D12,2)<6,"Weekday","Weekend") -> Weekday
A13: 12 | B13: =TEXT(Marketing!$D13,"MMMM") -> February | C13: =TEXT(Marketing!$D13,"DDDD") -> Tuesday | D13: 44229 | E13: facebook_tier1 | F13: social | G13: 349043 | H13: 478200 | I13: 18385.3 | J13: 2391 | K13: 48 | L13: 4 | M13: 17812 | N13: -0.00031182521 | O13: 5e-05 | P13: 0.00020075282 | Q13: 0.00083333333 | R13: =IF(Marketing!$L13=0, 0, Marketing!$M13/Marketing!$L13) -> 4453 | S13: =IF(Marketing!$J13=0,0,Marketing!$I13/Marketing!$J13) -> 7.6893768 | T13: =IF(Marketing!$K13=0,0,Marketing!$I13/Marketing!$K13) -> 383.02708 | U13: =Marketing!$M13 - Marketing!$I13 -> -573.3 | V13: =IF(Marketing!$L13=0,0,Marketing!$I13/Marketing!$L13) -> 4596.325 | W13: =IF(ISNUMBER(SEARCH("tier1",Marketing!$E13)),"Tier 1","Tier 2") -> Tier 1 | X13: =IF(ISNUMBER(SEARCH("tier1", E13)), "Tier 1", IF(ISNUMBER(SEARCH("tier2", E13)), "Tier 2", "Tier 2")) -> Tier 1 | Y13: =IF(WEEKDAY(Marketing!$D13,2)<6,"Weekday","Weekend") -> Weekday
... A309: 308 | B309: =TEXT(Marketing!$D309,"MMMM") -> February | C309: =TEXT(Marketing!$D309,"DDDD") -> Sunday | D309: 44255 | E309: banner_partner | F309: media | G309: 39889 | H309: 8490000 | I309: 6822.62 | J309: 849 | K309: 18 | L309: 2 | M309: 7030 | N309: 0.00030395948 | O309: 1e-06 | P309: 0.00021201413 | Q309: 0.0011111111 | R309: =IF(Marketing!$L309=0, 0, Marketing!$M309/Marketing!$L309) -> 3515 | S309: =IF(Marketing!$J309=0,0,Marketing!$I309/Marketing!$J309) -> 8.036066 | T309: =IF(Marketing!$K309=0,0,Marketing!$I309/Marketing!$K309) -> 379.03444 | U309: =Marketing!$M309 - Marketing!$I309 -> 207.38 | V309: =IF(Marketing!$L309=0,0,Marketing!$I309/Marketing!$L309) -> 3411.31 | W309: =IF(ISNUMBER(SEARCH("tier1",Marketing!$E309)),"Tier 1","Tier 2") -> Tier 2 | X309: =IF(ISNUMBER(SEARCH("tier1", E309)), "Tier 1", IF(ISNUMBER(SEARCH("tier2", E309)), "Tier 2", "Tier 2")) -> Tier 2 | Y309: =IF(WEEKDAY(Marketing!$D309,2)<6,"Weekday","Weekend") -> Weekend
I310: =SUM(Marketing[Mark spent]) -> 30590880 | L310: =SUM(Marketing[Orders]) -> 8043 | M310: =SUM(Marketing[Revenue]) -> 42889366 | N310: =(Marketing[[#Totals],[Revenue]]-Marketing[[#Totals],[Mark spent]])/Marketing[[#Totals],[Mark spent]] -> 0.40203114

Sheet Sheet1
A1: In this project, I used calculated fields a lot, learnt how to use it like measures in power bi. I wrote quite some calculated fields here.
A2: I also learnt how to create a combo chart, Clustered Column Chart with Dual Axes (Secondary Axis) in order to answer my question 4. When buyers are more active? What is the average revenue on weekdays and weekends?
A3: I used this combo a lot, used it to create a line combo too

Sheet Pivot Engine
A1: 1. What is the OVERALL MOI? | B1: =(Marketing[[#Totals],[Revenue]]-Marketing[[#Totals],[Mark spent]])/Marketing[[#Totals],[Mark spent]] -> 0.40203114
A3: Overall_ROMI
A4: 0.40203114
A11: 2. What are the ROMIs by campaigns?
A12: Campaign Name | B12: Total Campaign ROMI
A13: youtube_blogger | B13: 2.7732066
A14: facebook_retargeting | B14: 1.0149608
A15: google_hot | B15: 0.8381244
A16: instagram_tier1 | B16: 0.77139683
A17: instagram_blogger | B17: 0.36754211
A18: banner_partner | B18: 0.22406169
A19: facebook_tier1 | B19: -0.065651087
A20: Facebook_tier2 | B20: -0.26216421
A21: google_wide | B21: -0.33670274
A22: instagram_tier2 | B22: -0.37114136
A23: facebook_lal | B23: -0.88635886
A24: Grand Total | B24: 0.40203114
A28: 3
A29: Calendar Date | B29: Total Revenue | C29: Total Mark spent
A30: 44228 | B30: 182676 | C30: 120844.72
A31: 44229 | B31: 316369 | C31: 189064.91
A32: 44230 | B32: 1583142 | C32: 922808.01
A33: 44231 | B33: 1633899 | C33: 1168337.3
A34: 44232 | B34: 2704723 | C34: 1883989.7
A35: 44233 | B35: 416199 | C35: 305983.26
A36: 44234 | B36: 434647 | C36: 306417.68
A37: 44235 | B37: 308655 | C37: 228203.45
A38: 44236 | B38: 437923 | C38: 313716.54
A39: 44237 | B39: 811363 | C39: 729951.8
A40: 44238 | B40: 1563209 | C40: 919245.87
A41: 44239 | B41: 1657464 | C41: 1155208.8
... A57: 44255 | B57: 76164 | C57: 53362.67
A58: Grand Total | B58: 42889366 | C58: 30590880
A61: Date | B61: Total True_CR2
A62: 44252 | B62: 0.15037594
A63: 44246 | B63: 0.14321948
A64: 44229 | B64: 0.13989637
A65: 44251 | B65: 0.1377709
A66: 44244 | B66: 0.13239953
A67: 44240 | B67: 0.13165829
...

Sheet Introduction

Sheet Dashboard
